// phil welsby - 21 aug 2021 - catch

async function foo() {
   const p1 = new Promise((resolve) => setTimeout(() => resolve('1'), 1000))
   const p2 = new Promise((_,reject) => setTimeout(() => reject('2'), 500))
   const results = [await p1, await p2] // Do not do this! Use Promise.all or Promise.allSettled instead.
}
foo().catch(() => {}) // Attempt to swallow all errors...

